[django.request 2024-04-03 19:05:09 log.py: 241 - log_response()] Not Found: /api/v1/resend_code/
[django.request 2024-04-03 19:05:09 log.py: 241 - log_response()] Too Many Requests: /api/v1/resend_code/
[django.request 2024-04-03 19:05:09 log.py: 241 - log_response()] Too Many Requests: /api/v1/resend_code/
[django.request 2024-04-03 19:05:09 log.py: 241 - log_response()] Too Many Requests: /api/v1/resend_code/
[django.request 2024-04-03 19:05:09 log.py: 241 - log_response()] Too Many Requests: /api/v1/resend_code/
[django.request 2024-04-03 19:05:10 log.py: 241 - log_response()] Bad Request: /api/v1/token/refresh/
[django.request 2024-04-03 19:05:10 log.py: 241 - log_response()] Bad Request: /api/v1/user/
[django.request 2024-04-03 19:05:10 log.py: 241 - log_response()] Bad Request: /api/v1/user/
[django.request 2024-04-03 19:05:10 log.py: 241 - log_response()] Bad Request: /api/v1/user/
[django.request 2024-04-03 19:05:10 log.py: 241 - log_response()] Bad Request: /api/v1/user/
[django.request 2024-04-03 19:05:10 log.py: 241 - log_response()] Bad Request: /api/v1/user/
[django.request 2024-04-03 19:05:10 log.py: 241 - log_response()] Bad Request: /api/v1/user/
[django.request 2024-04-03 19:05:10 log.py: 241 - log_response()] Unauthorized: /api/v1/me/
[django.request 2024-04-03 19:05:10 log.py: 241 - log_response()] Bad Request: /api/v1/user/
[django.request 2024-04-03 19:10:09 log.py: 241 - log_response()] Not Found: /api/v1/resend_code/
[django.request 2024-04-03 19:10:09 log.py: 241 - log_response()] Too Many Requests: /api/v1/resend_code/
[django.request 2024-04-03 19:10:09 log.py: 241 - log_response()] Too Many Requests: /api/v1/resend_code/
[django.request 2024-04-03 19:10:09 log.py: 241 - log_response()] Too Many Requests: /api/v1/resend_code/
[django.request 2024-04-03 19:10:09 log.py: 241 - log_response()] Too Many Requests: /api/v1/resend_code/
[django.request 2024-04-03 19:10:09 log.py: 241 - log_response()] Bad Request: /api/v1/token/refresh/
[django.request 2024-04-03 19:10:09 log.py: 241 - log_response()] Bad Request: /api/v1/user/
[django.request 2024-04-03 19:10:09 log.py: 241 - log_response()] Bad Request: /api/v1/user/
[django.request 2024-04-03 19:10:09 log.py: 241 - log_response()] Bad Request: /api/v1/user/
[django.request 2024-04-03 19:10:09 log.py: 241 - log_response()] Bad Request: /api/v1/user/
[django.request 2024-04-03 19:10:09 log.py: 241 - log_response()] Bad Request: /api/v1/user/
[django.request 2024-04-03 19:10:09 log.py: 241 - log_response()] Bad Request: /api/v1/user/
[django.request 2024-04-03 19:10:10 log.py: 241 - log_response()] Unauthorized: /api/v1/me/
[django.request 2024-04-03 19:10:10 log.py: 241 - log_response()] Bad Request: /api/v1/user/
[django.request 2024-04-03 19:15:20 log.py: 241 - log_response()] Not Found: /api/v1/resend_code/
[django.request 2024-04-03 19:15:20 log.py: 241 - log_response()] Too Many Requests: /api/v1/resend_code/
[django.request 2024-04-03 19:15:20 log.py: 241 - log_response()] Too Many Requests: /api/v1/resend_code/
[django.request 2024-04-03 19:15:20 log.py: 241 - log_response()] Too Many Requests: /api/v1/resend_code/
[django.request 2024-04-03 19:15:20 log.py: 241 - log_response()] Too Many Requests: /api/v1/resend_code/
[django.request 2024-04-03 19:15:20 log.py: 241 - log_response()] Bad Request: /api/v1/token/refresh/
[django.request 2024-04-03 19:15:20 log.py: 241 - log_response()] Bad Request: /api/v1/user/
[django.request 2024-04-03 19:15:20 log.py: 241 - log_response()] Bad Request: /api/v1/user/
[django.request 2024-04-03 19:15:20 log.py: 241 - log_response()] Bad Request: /api/v1/user/
[django.request 2024-04-03 19:15:20 log.py: 241 - log_response()] Bad Request: /api/v1/user/
[django.request 2024-04-03 19:15:20 log.py: 241 - log_response()] Bad Request: /api/v1/user/
[django.request 2024-04-03 19:15:20 log.py: 241 - log_response()] Bad Request: /api/v1/user/
[django.request 2024-04-03 19:15:21 log.py: 241 - log_response()] Unauthorized: /api/v1/me/
[django.request 2024-04-03 19:15:21 log.py: 241 - log_response()] Bad Request: /api/v1/user/
[django.request 2024-04-03 19:19:12 log.py: 241 - log_response()] Not Found: /api/v1/resend_code/
[django.request 2024-04-03 19:19:12 log.py: 241 - log_response()] Too Many Requests: /api/v1/resend_code/
[django.request 2024-04-03 19:19:12 log.py: 241 - log_response()] Too Many Requests: /api/v1/resend_code/
[django.request 2024-04-03 19:19:12 log.py: 241 - log_response()] Too Many Requests: /api/v1/resend_code/
[django.request 2024-04-03 19:19:12 log.py: 241 - log_response()] Too Many Requests: /api/v1/resend_code/
[django.request 2024-04-03 19:19:12 log.py: 241 - log_response()] Bad Request: /api/v1/token/refresh/
[django.request 2024-04-03 19:19:12 log.py: 241 - log_response()] Bad Request: /api/v1/user/
[django.request 2024-04-03 19:19:13 log.py: 241 - log_response()] Bad Request: /api/v1/user/
[django.request 2024-04-03 19:19:13 log.py: 241 - log_response()] Bad Request: /api/v1/user/
[django.request 2024-04-03 19:19:13 log.py: 241 - log_response()] Bad Request: /api/v1/user/
[django.request 2024-04-03 19:19:13 log.py: 241 - log_response()] Bad Request: /api/v1/user/
[django.request 2024-04-03 19:19:13 log.py: 241 - log_response()] Bad Request: /api/v1/user/
[django.request 2024-04-03 19:19:13 log.py: 241 - log_response()] Unauthorized: /api/v1/me/
[django.request 2024-04-03 19:19:13 log.py: 241 - log_response()] Bad Request: /api/v1/user/
[django.request 2024-04-03 19:19:57 log.py: 241 - log_response()] Not Found: /api/v1/resend_code/
[django.request 2024-04-03 19:19:57 log.py: 241 - log_response()] Too Many Requests: /api/v1/resend_code/
[django.request 2024-04-03 19:19:57 log.py: 241 - log_response()] Too Many Requests: /api/v1/resend_code/
[django.request 2024-04-03 19:19:57 log.py: 241 - log_response()] Too Many Requests: /api/v1/resend_code/
[django.request 2024-04-03 19:19:57 log.py: 241 - log_response()] Too Many Requests: /api/v1/resend_code/
[django.request 2024-04-03 19:19:58 log.py: 241 - log_response()] Bad Request: /api/v1/token/refresh/
[django.request 2024-04-03 19:19:58 log.py: 241 - log_response()] Bad Request: /api/v1/user/
[django.request 2024-04-03 19:19:58 log.py: 241 - log_response()] Bad Request: /api/v1/user/
[django.request 2024-04-03 19:19:58 log.py: 241 - log_response()] Bad Request: /api/v1/user/
[django.request 2024-04-03 19:19:58 log.py: 241 - log_response()] Bad Request: /api/v1/user/
[django.request 2024-04-03 19:19:58 log.py: 241 - log_response()] Bad Request: /api/v1/user/
[django.request 2024-04-03 19:19:58 log.py: 241 - log_response()] Bad Request: /api/v1/user/
[django.request 2024-04-03 19:19:58 log.py: 241 - log_response()] Unauthorized: /api/v1/me/
[django.request 2024-04-03 19:19:58 log.py: 241 - log_response()] Bad Request: /api/v1/user/
[django.request 2024-04-03 19:20:03 log.py: 241 - log_response()] Not Found: /api/v1/resend_code/
[django.request 2024-04-03 19:20:03 log.py: 241 - log_response()] Too Many Requests: /api/v1/resend_code/
[django.request 2024-04-03 19:20:03 log.py: 241 - log_response()] Too Many Requests: /api/v1/resend_code/
[django.request 2024-04-03 19:20:03 log.py: 241 - log_response()] Too Many Requests: /api/v1/resend_code/
[django.request 2024-04-03 19:20:03 log.py: 241 - log_response()] Too Many Requests: /api/v1/resend_code/
[django.request 2024-04-03 19:20:03 log.py: 241 - log_response()] Bad Request: /api/v1/token/refresh/
[django.request 2024-04-03 19:20:03 log.py: 241 - log_response()] Bad Request: /api/v1/user/
[django.request 2024-04-03 19:20:03 log.py: 241 - log_response()] Bad Request: /api/v1/user/
[django.request 2024-04-03 19:20:03 log.py: 241 - log_response()] Bad Request: /api/v1/user/
[django.request 2024-04-03 19:20:03 log.py: 241 - log_response()] Bad Request: /api/v1/user/
[django.request 2024-04-03 19:20:03 log.py: 241 - log_response()] Bad Request: /api/v1/user/
[django.request 2024-04-03 19:20:03 log.py: 241 - log_response()] Bad Request: /api/v1/user/
[django.request 2024-04-03 19:20:04 log.py: 241 - log_response()] Unauthorized: /api/v1/me/
[django.request 2024-04-03 19:20:04 log.py: 241 - log_response()] Bad Request: /api/v1/user/
[django.request 2024-04-03 19:20:52 log.py: 241 - log_response()] Not Found: /api/v1/resend_code/
[django.request 2024-04-03 19:20:52 log.py: 241 - log_response()] Too Many Requests: /api/v1/resend_code/
[django.request 2024-04-03 19:20:52 log.py: 241 - log_response()] Too Many Requests: /api/v1/resend_code/
[django.request 2024-04-03 19:20:52 log.py: 241 - log_response()] Too Many Requests: /api/v1/resend_code/
[django.request 2024-04-03 19:20:52 log.py: 241 - log_response()] Too Many Requests: /api/v1/resend_code/
[django.request 2024-04-03 19:20:52 log.py: 241 - log_response()] Bad Request: /api/v1/token/refresh/
[django.request 2024-04-03 19:20:52 log.py: 241 - log_response()] Bad Request: /api/v1/user/
[django.request 2024-04-03 19:20:52 log.py: 241 - log_response()] Bad Request: /api/v1/user/
[django.request 2024-04-03 19:20:52 log.py: 241 - log_response()] Bad Request: /api/v1/user/
[django.request 2024-04-03 19:20:52 log.py: 241 - log_response()] Bad Request: /api/v1/user/
[django.request 2024-04-03 19:20:52 log.py: 241 - log_response()] Bad Request: /api/v1/user/
[django.request 2024-04-03 19:20:52 log.py: 241 - log_response()] Bad Request: /api/v1/user/
[django.request 2024-04-03 19:20:53 log.py: 241 - log_response()] Unauthorized: /api/v1/me/
[django.request 2024-04-03 19:20:53 log.py: 241 - log_response()] Bad Request: /api/v1/user/
[django.request 2024-04-03 19:26:54 log.py: 241 - log_response()] Not Found: /api/v1/resend_code/
[django.request 2024-04-03 19:26:54 log.py: 241 - log_response()] Too Many Requests: /api/v1/resend_code/
[django.request 2024-04-03 19:26:54 log.py: 241 - log_response()] Too Many Requests: /api/v1/resend_code/
[django.request 2024-04-03 19:26:54 log.py: 241 - log_response()] Too Many Requests: /api/v1/resend_code/
[django.request 2024-04-03 19:26:54 log.py: 241 - log_response()] Too Many Requests: /api/v1/resend_code/
[django.request 2024-04-03 19:26:55 log.py: 241 - log_response()] Bad Request: /api/v1/token/refresh/
[django.request 2024-04-03 19:26:55 log.py: 241 - log_response()] Bad Request: /api/v1/user/
[django.request 2024-04-03 19:26:55 log.py: 241 - log_response()] Bad Request: /api/v1/user/
[django.request 2024-04-03 19:26:55 log.py: 241 - log_response()] Bad Request: /api/v1/user/
[django.request 2024-04-03 19:26:55 log.py: 241 - log_response()] Bad Request: /api/v1/user/
[django.request 2024-04-03 19:26:55 log.py: 241 - log_response()] Bad Request: /api/v1/user/
[django.request 2024-04-03 19:26:55 log.py: 241 - log_response()] Bad Request: /api/v1/user/
[django.request 2024-04-03 19:26:55 log.py: 241 - log_response()] Unauthorized: /api/v1/me/
[django.request 2024-04-03 19:26:55 log.py: 241 - log_response()] Bad Request: /api/v1/user/
[django.request 2024-04-03 19:37:15 log.py: 241 - log_response()] Not Found: /api/v1/resend_code/
[django.request 2024-04-03 19:37:15 log.py: 241 - log_response()] Too Many Requests: /api/v1/resend_code/
[django.request 2024-04-03 19:37:15 log.py: 241 - log_response()] Too Many Requests: /api/v1/resend_code/
[django.request 2024-04-03 19:37:15 log.py: 241 - log_response()] Too Many Requests: /api/v1/resend_code/
[django.request 2024-04-03 19:37:15 log.py: 241 - log_response()] Too Many Requests: /api/v1/resend_code/
[django.request 2024-04-03 19:37:15 log.py: 241 - log_response()] Bad Request: /api/v1/token/refresh/
[django.request 2024-04-03 19:37:15 log.py: 241 - log_response()] Bad Request: /api/v1/user/
[django.request 2024-04-03 19:37:15 log.py: 241 - log_response()] Bad Request: /api/v1/user/
[django.request 2024-04-03 19:37:15 log.py: 241 - log_response()] Bad Request: /api/v1/user/
[django.request 2024-04-03 19:37:15 log.py: 241 - log_response()] Bad Request: /api/v1/user/
[django.request 2024-04-03 19:37:15 log.py: 241 - log_response()] Bad Request: /api/v1/user/
[django.request 2024-04-03 19:37:15 log.py: 241 - log_response()] Bad Request: /api/v1/user/
[django.request 2024-04-03 19:37:16 log.py: 241 - log_response()] Unauthorized: /api/v1/me/
[django.request 2024-04-03 19:37:16 log.py: 241 - log_response()] Bad Request: /api/v1/user/
[django.request 2024-04-03 19:37:37 log.py: 241 - log_response()] Not Found: /api/v1/resend_code/
[django.request 2024-04-03 19:37:37 log.py: 241 - log_response()] Too Many Requests: /api/v1/resend_code/
[django.request 2024-04-03 19:37:37 log.py: 241 - log_response()] Too Many Requests: /api/v1/resend_code/
[django.request 2024-04-03 19:37:37 log.py: 241 - log_response()] Too Many Requests: /api/v1/resend_code/
[django.request 2024-04-03 19:37:37 log.py: 241 - log_response()] Too Many Requests: /api/v1/resend_code/
[django.request 2024-04-03 19:37:37 log.py: 241 - log_response()] Bad Request: /api/v1/token/refresh/
[django.request 2024-04-03 19:37:37 log.py: 241 - log_response()] Bad Request: /api/v1/user/
[django.request 2024-04-03 19:37:37 log.py: 241 - log_response()] Bad Request: /api/v1/user/
[django.request 2024-04-03 19:37:37 log.py: 241 - log_response()] Bad Request: /api/v1/user/
[django.request 2024-04-03 19:37:37 log.py: 241 - log_response()] Bad Request: /api/v1/user/
[django.request 2024-04-03 19:37:37 log.py: 241 - log_response()] Bad Request: /api/v1/user/
[django.request 2024-04-03 19:37:37 log.py: 241 - log_response()] Bad Request: /api/v1/user/
[django.request 2024-04-03 19:37:38 log.py: 241 - log_response()] Unauthorized: /api/v1/me/
[django.request 2024-04-03 19:37:38 log.py: 241 - log_response()] Bad Request: /api/v1/user/
[django.request 2024-04-03 19:37:50 log.py: 241 - log_response()] Internal Server Error: /api/v1/history/
Traceback (most recent call last):
  File "/Users/holo/Library/Caches/pypoetry/virtualenvs/diary-workout-tracker-backend-ZDA_NhFM-py3.11/lib/python3.11/site-packages/django/core/handlers/exception.py", line 55, in inner
    response = get_response(request)
               ^^^^^^^^^^^^^^^^^^^^^
  File "/Users/holo/Library/Caches/pypoetry/virtualenvs/diary-workout-tracker-backend-ZDA_NhFM-py3.11/lib/python3.11/site-packages/django/core/handlers/base.py", line 197, in _get_response
    response = wrapped_callback(request, *callback_args, **callback_kwargs)
               ^^^^^^^^^^^^^^^^^^^^^^^^^^^^^^^^^^^^^^^^^^^^^^^^^^^^^^^^^^^^
  File "/Users/holo/Library/Caches/pypoetry/virtualenvs/diary-workout-tracker-backend-ZDA_NhFM-py3.11/lib/python3.11/site-packages/django/views/decorators/csrf.py", line 65, in _view_wrapper
    return view_func(request, *args, **kwargs)
           ^^^^^^^^^^^^^^^^^^^^^^^^^^^^^^^^^^^
  File "/Users/holo/Library/Caches/pypoetry/virtualenvs/diary-workout-tracker-backend-ZDA_NhFM-py3.11/lib/python3.11/site-packages/django/views/generic/base.py", line 104, in view
    return self.dispatch(request, *args, **kwargs)
           ^^^^^^^^^^^^^^^^^^^^^^^^^^^^^^^^^^^^^^^
  File "/Users/holo/Library/Caches/pypoetry/virtualenvs/diary-workout-tracker-backend-ZDA_NhFM-py3.11/lib/python3.11/site-packages/rest_framework/views.py", line 509, in dispatch
    response = self.handle_exception(exc)
               ^^^^^^^^^^^^^^^^^^^^^^^^^^
  File "/Users/holo/Library/Caches/pypoetry/virtualenvs/diary-workout-tracker-backend-ZDA_NhFM-py3.11/lib/python3.11/site-packages/rest_framework/views.py", line 469, in handle_exception
    self.raise_uncaught_exception(exc)
  File "/Users/holo/Library/Caches/pypoetry/virtualenvs/diary-workout-tracker-backend-ZDA_NhFM-py3.11/lib/python3.11/site-packages/rest_framework/views.py", line 480, in raise_uncaught_exception
    raise exc
  File "/Users/holo/Library/Caches/pypoetry/virtualenvs/diary-workout-tracker-backend-ZDA_NhFM-py3.11/lib/python3.11/site-packages/rest_framework/views.py", line 506, in dispatch
    response = handler(request, *args, **kwargs)
               ^^^^^^^^^^^^^^^^^^^^^^^^^^^^^^^^^
  File "/Users/holo/Library/Caches/pypoetry/virtualenvs/diary-workout-tracker-backend-ZDA_NhFM-py3.11/lib/python3.11/site-packages/drf_spectacular/drainage.py", line 207, in wrapped_method
    return method(self, request, *args, **kwargs)
           ^^^^^^^^^^^^^^^^^^^^^^^^^^^^^^^^^^^^^^
  File "/Users/holo/Library/Caches/pypoetry/virtualenvs/diary-workout-tracker-backend-ZDA_NhFM-py3.11/lib/python3.11/site-packages/rest_framework/generics.py", line 242, in post
    return self.create(request, *args, **kwargs)
           ^^^^^^^^^^^^^^^^^^^^^^^^^^^^^^^^^^^^^
  File "/Users/holo/Dev/diary-workout-tracker-backend/backend/api/v1/views.py", line 206, in create
    updater.update_achievements()
  File "/Users/holo/Dev/diary-workout-tracker-backend/backend/utils/achievements.py", line 129, in update_achievements
    self._check_for_new_backend_achievements()
  File "/Users/holo/Dev/diary-workout-tracker-backend/backend/utils/achievements.py", line 155, in _check_for_new_backend_achievements
    if validator is not None and validator(user=self._user, history=self._history):
                                 ^^^^^^^^^^^^^^^^^^^^^^^^^^^^^^^^^^^^^^^^^^^^^^^^^
  File "/Users/holo/Dev/diary-workout-tracker-backend/backend/utils/achievements.py", line 14, in tourist
    if history.day_number == 1:
       ^^^^^^^^^^^^^^^^^^
AttributeError: 'History' object has no attribute 'day_number'
[django.request 2024-04-03 19:37:51 log.py: 241 - log_response()] Internal Server Error: /api/v1/history/
Traceback (most recent call last):
  File "/Users/holo/Library/Caches/pypoetry/virtualenvs/diary-workout-tracker-backend-ZDA_NhFM-py3.11/lib/python3.11/site-packages/django/core/handlers/exception.py", line 55, in inner
    response = get_response(request)
               ^^^^^^^^^^^^^^^^^^^^^
  File "/Users/holo/Library/Caches/pypoetry/virtualenvs/diary-workout-tracker-backend-ZDA_NhFM-py3.11/lib/python3.11/site-packages/django/core/handlers/base.py", line 197, in _get_response
    response = wrapped_callback(request, *callback_args, **callback_kwargs)
               ^^^^^^^^^^^^^^^^^^^^^^^^^^^^^^^^^^^^^^^^^^^^^^^^^^^^^^^^^^^^
  File "/Users/holo/Library/Caches/pypoetry/virtualenvs/diary-workout-tracker-backend-ZDA_NhFM-py3.11/lib/python3.11/site-packages/django/views/decorators/csrf.py", line 65, in _view_wrapper
    return view_func(request, *args, **kwargs)
           ^^^^^^^^^^^^^^^^^^^^^^^^^^^^^^^^^^^
  File "/Users/holo/Library/Caches/pypoetry/virtualenvs/diary-workout-tracker-backend-ZDA_NhFM-py3.11/lib/python3.11/site-packages/django/views/generic/base.py", line 104, in view
    return self.dispatch(request, *args, **kwargs)
           ^^^^^^^^^^^^^^^^^^^^^^^^^^^^^^^^^^^^^^^
  File "/Users/holo/Library/Caches/pypoetry/virtualenvs/diary-workout-tracker-backend-ZDA_NhFM-py3.11/lib/python3.11/site-packages/rest_framework/views.py", line 509, in dispatch
    response = self.handle_exception(exc)
               ^^^^^^^^^^^^^^^^^^^^^^^^^^
  File "/Users/holo/Library/Caches/pypoetry/virtualenvs/diary-workout-tracker-backend-ZDA_NhFM-py3.11/lib/python3.11/site-packages/rest_framework/views.py", line 469, in handle_exception
    self.raise_uncaught_exception(exc)
  File "/Users/holo/Library/Caches/pypoetry/virtualenvs/diary-workout-tracker-backend-ZDA_NhFM-py3.11/lib/python3.11/site-packages/rest_framework/views.py", line 480, in raise_uncaught_exception
    raise exc
  File "/Users/holo/Library/Caches/pypoetry/virtualenvs/diary-workout-tracker-backend-ZDA_NhFM-py3.11/lib/python3.11/site-packages/rest_framework/views.py", line 506, in dispatch
    response = handler(request, *args, **kwargs)
               ^^^^^^^^^^^^^^^^^^^^^^^^^^^^^^^^^
  File "/Users/holo/Library/Caches/pypoetry/virtualenvs/diary-workout-tracker-backend-ZDA_NhFM-py3.11/lib/python3.11/site-packages/drf_spectacular/drainage.py", line 207, in wrapped_method
    return method(self, request, *args, **kwargs)
           ^^^^^^^^^^^^^^^^^^^^^^^^^^^^^^^^^^^^^^
  File "/Users/holo/Library/Caches/pypoetry/virtualenvs/diary-workout-tracker-backend-ZDA_NhFM-py3.11/lib/python3.11/site-packages/rest_framework/generics.py", line 242, in post
    return self.create(request, *args, **kwargs)
           ^^^^^^^^^^^^^^^^^^^^^^^^^^^^^^^^^^^^^
  File "/Users/holo/Dev/diary-workout-tracker-backend/backend/api/v1/views.py", line 206, in create
    updater.update_achievements()
  File "/Users/holo/Dev/diary-workout-tracker-backend/backend/utils/achievements.py", line 129, in update_achievements
    self._check_for_new_backend_achievements()
  File "/Users/holo/Dev/diary-workout-tracker-backend/backend/utils/achievements.py", line 155, in _check_for_new_backend_achievements
    if validator is not None and validator(user=self._user, history=self._history):
                                 ^^^^^^^^^^^^^^^^^^^^^^^^^^^^^^^^^^^^^^^^^^^^^^^^^
  File "/Users/holo/Dev/diary-workout-tracker-backend/backend/utils/achievements.py", line 14, in tourist
    if history.day_number == 1:
       ^^^^^^^^^^^^^^^^^^
AttributeError: 'History' object has no attribute 'day_number'
[django.request 2024-04-03 19:37:51 log.py: 241 - log_response()] Internal Server Error: /api/v1/history/
Traceback (most recent call last):
  File "/Users/holo/Library/Caches/pypoetry/virtualenvs/diary-workout-tracker-backend-ZDA_NhFM-py3.11/lib/python3.11/site-packages/django/core/handlers/exception.py", line 55, in inner
    response = get_response(request)
               ^^^^^^^^^^^^^^^^^^^^^
  File "/Users/holo/Library/Caches/pypoetry/virtualenvs/diary-workout-tracker-backend-ZDA_NhFM-py3.11/lib/python3.11/site-packages/django/core/handlers/base.py", line 197, in _get_response
    response = wrapped_callback(request, *callback_args, **callback_kwargs)
               ^^^^^^^^^^^^^^^^^^^^^^^^^^^^^^^^^^^^^^^^^^^^^^^^^^^^^^^^^^^^
  File "/Users/holo/Library/Caches/pypoetry/virtualenvs/diary-workout-tracker-backend-ZDA_NhFM-py3.11/lib/python3.11/site-packages/django/views/decorators/csrf.py", line 65, in _view_wrapper
    return view_func(request, *args, **kwargs)
           ^^^^^^^^^^^^^^^^^^^^^^^^^^^^^^^^^^^
  File "/Users/holo/Library/Caches/pypoetry/virtualenvs/diary-workout-tracker-backend-ZDA_NhFM-py3.11/lib/python3.11/site-packages/django/views/generic/base.py", line 104, in view
    return self.dispatch(request, *args, **kwargs)
           ^^^^^^^^^^^^^^^^^^^^^^^^^^^^^^^^^^^^^^^
  File "/Users/holo/Library/Caches/pypoetry/virtualenvs/diary-workout-tracker-backend-ZDA_NhFM-py3.11/lib/python3.11/site-packages/rest_framework/views.py", line 509, in dispatch
    response = self.handle_exception(exc)
               ^^^^^^^^^^^^^^^^^^^^^^^^^^
  File "/Users/holo/Library/Caches/pypoetry/virtualenvs/diary-workout-tracker-backend-ZDA_NhFM-py3.11/lib/python3.11/site-packages/rest_framework/views.py", line 469, in handle_exception
    self.raise_uncaught_exception(exc)
  File "/Users/holo/Library/Caches/pypoetry/virtualenvs/diary-workout-tracker-backend-ZDA_NhFM-py3.11/lib/python3.11/site-packages/rest_framework/views.py", line 480, in raise_uncaught_exception
    raise exc
  File "/Users/holo/Library/Caches/pypoetry/virtualenvs/diary-workout-tracker-backend-ZDA_NhFM-py3.11/lib/python3.11/site-packages/rest_framework/views.py", line 506, in dispatch
    response = handler(request, *args, **kwargs)
               ^^^^^^^^^^^^^^^^^^^^^^^^^^^^^^^^^
  File "/Users/holo/Library/Caches/pypoetry/virtualenvs/diary-workout-tracker-backend-ZDA_NhFM-py3.11/lib/python3.11/site-packages/drf_spectacular/drainage.py", line 207, in wrapped_method
    return method(self, request, *args, **kwargs)
           ^^^^^^^^^^^^^^^^^^^^^^^^^^^^^^^^^^^^^^
  File "/Users/holo/Library/Caches/pypoetry/virtualenvs/diary-workout-tracker-backend-ZDA_NhFM-py3.11/lib/python3.11/site-packages/rest_framework/generics.py", line 242, in post
    return self.create(request, *args, **kwargs)
           ^^^^^^^^^^^^^^^^^^^^^^^^^^^^^^^^^^^^^
  File "/Users/holo/Dev/diary-workout-tracker-backend/backend/api/v1/views.py", line 206, in create
    updater.update_achievements()
  File "/Users/holo/Dev/diary-workout-tracker-backend/backend/utils/achievements.py", line 129, in update_achievements
    self._check_for_new_backend_achievements()
  File "/Users/holo/Dev/diary-workout-tracker-backend/backend/utils/achievements.py", line 155, in _check_for_new_backend_achievements
    if validator is not None and validator(user=self._user, history=self._history):
                                 ^^^^^^^^^^^^^^^^^^^^^^^^^^^^^^^^^^^^^^^^^^^^^^^^^
  File "/Users/holo/Dev/diary-workout-tracker-backend/backend/utils/achievements.py", line 14, in tourist
    if history.day_number == 1:
       ^^^^^^^^^^^^^^^^^^
AttributeError: 'History' object has no attribute 'day_number'
[django.request 2024-04-03 19:37:51 log.py: 241 - log_response()] Internal Server Error: /api/v1/history/
Traceback (most recent call last):
  File "/Users/holo/Library/Caches/pypoetry/virtualenvs/diary-workout-tracker-backend-ZDA_NhFM-py3.11/lib/python3.11/site-packages/django/core/handlers/exception.py", line 55, in inner
    response = get_response(request)
               ^^^^^^^^^^^^^^^^^^^^^
  File "/Users/holo/Library/Caches/pypoetry/virtualenvs/diary-workout-tracker-backend-ZDA_NhFM-py3.11/lib/python3.11/site-packages/django/core/handlers/base.py", line 197, in _get_response
    response = wrapped_callback(request, *callback_args, **callback_kwargs)
               ^^^^^^^^^^^^^^^^^^^^^^^^^^^^^^^^^^^^^^^^^^^^^^^^^^^^^^^^^^^^
  File "/Users/holo/Library/Caches/pypoetry/virtualenvs/diary-workout-tracker-backend-ZDA_NhFM-py3.11/lib/python3.11/site-packages/django/views/decorators/csrf.py", line 65, in _view_wrapper
    return view_func(request, *args, **kwargs)
           ^^^^^^^^^^^^^^^^^^^^^^^^^^^^^^^^^^^
  File "/Users/holo/Library/Caches/pypoetry/virtualenvs/diary-workout-tracker-backend-ZDA_NhFM-py3.11/lib/python3.11/site-packages/django/views/generic/base.py", line 104, in view
    return self.dispatch(request, *args, **kwargs)
           ^^^^^^^^^^^^^^^^^^^^^^^^^^^^^^^^^^^^^^^
  File "/Users/holo/Library/Caches/pypoetry/virtualenvs/diary-workout-tracker-backend-ZDA_NhFM-py3.11/lib/python3.11/site-packages/rest_framework/views.py", line 509, in dispatch
    response = self.handle_exception(exc)
               ^^^^^^^^^^^^^^^^^^^^^^^^^^
  File "/Users/holo/Library/Caches/pypoetry/virtualenvs/diary-workout-tracker-backend-ZDA_NhFM-py3.11/lib/python3.11/site-packages/rest_framework/views.py", line 469, in handle_exception
    self.raise_uncaught_exception(exc)
  File "/Users/holo/Library/Caches/pypoetry/virtualenvs/diary-workout-tracker-backend-ZDA_NhFM-py3.11/lib/python3.11/site-packages/rest_framework/views.py", line 480, in raise_uncaught_exception
    raise exc
  File "/Users/holo/Library/Caches/pypoetry/virtualenvs/diary-workout-tracker-backend-ZDA_NhFM-py3.11/lib/python3.11/site-packages/rest_framework/views.py", line 506, in dispatch
    response = handler(request, *args, **kwargs)
               ^^^^^^^^^^^^^^^^^^^^^^^^^^^^^^^^^
  File "/Users/holo/Library/Caches/pypoetry/virtualenvs/diary-workout-tracker-backend-ZDA_NhFM-py3.11/lib/python3.11/site-packages/drf_spectacular/drainage.py", line 207, in wrapped_method
    return method(self, request, *args, **kwargs)
           ^^^^^^^^^^^^^^^^^^^^^^^^^^^^^^^^^^^^^^
  File "/Users/holo/Library/Caches/pypoetry/virtualenvs/diary-workout-tracker-backend-ZDA_NhFM-py3.11/lib/python3.11/site-packages/rest_framework/generics.py", line 242, in post
    return self.create(request, *args, **kwargs)
           ^^^^^^^^^^^^^^^^^^^^^^^^^^^^^^^^^^^^^
  File "/Users/holo/Dev/diary-workout-tracker-backend/backend/api/v1/views.py", line 206, in create
    updater.update_achievements()
  File "/Users/holo/Dev/diary-workout-tracker-backend/backend/utils/achievements.py", line 129, in update_achievements
    self._check_for_new_backend_achievements()
  File "/Users/holo/Dev/diary-workout-tracker-backend/backend/utils/achievements.py", line 155, in _check_for_new_backend_achievements
    if validator is not None and validator(user=self._user, history=self._history):
                                 ^^^^^^^^^^^^^^^^^^^^^^^^^^^^^^^^^^^^^^^^^^^^^^^^^
  File "/Users/holo/Dev/diary-workout-tracker-backend/backend/utils/achievements.py", line 14, in tourist
    if history.day_number == 1:
       ^^^^^^^^^^^^^^^^^^
AttributeError: 'History' object has no attribute 'day_number'
[django.request 2024-04-03 19:37:51 log.py: 241 - log_response()] Internal Server Error: /api/v1/history/
Traceback (most recent call last):
  File "/Users/holo/Library/Caches/pypoetry/virtualenvs/diary-workout-tracker-backend-ZDA_NhFM-py3.11/lib/python3.11/site-packages/django/core/handlers/exception.py", line 55, in inner
    response = get_response(request)
               ^^^^^^^^^^^^^^^^^^^^^
  File "/Users/holo/Library/Caches/pypoetry/virtualenvs/diary-workout-tracker-backend-ZDA_NhFM-py3.11/lib/python3.11/site-packages/django/core/handlers/base.py", line 197, in _get_response
    response = wrapped_callback(request, *callback_args, **callback_kwargs)
               ^^^^^^^^^^^^^^^^^^^^^^^^^^^^^^^^^^^^^^^^^^^^^^^^^^^^^^^^^^^^
  File "/Users/holo/Library/Caches/pypoetry/virtualenvs/diary-workout-tracker-backend-ZDA_NhFM-py3.11/lib/python3.11/site-packages/django/views/decorators/csrf.py", line 65, in _view_wrapper
    return view_func(request, *args, **kwargs)
           ^^^^^^^^^^^^^^^^^^^^^^^^^^^^^^^^^^^
  File "/Users/holo/Library/Caches/pypoetry/virtualenvs/diary-workout-tracker-backend-ZDA_NhFM-py3.11/lib/python3.11/site-packages/django/views/generic/base.py", line 104, in view
    return self.dispatch(request, *args, **kwargs)
           ^^^^^^^^^^^^^^^^^^^^^^^^^^^^^^^^^^^^^^^
  File "/Users/holo/Library/Caches/pypoetry/virtualenvs/diary-workout-tracker-backend-ZDA_NhFM-py3.11/lib/python3.11/site-packages/rest_framework/views.py", line 509, in dispatch
    response = self.handle_exception(exc)
               ^^^^^^^^^^^^^^^^^^^^^^^^^^
  File "/Users/holo/Library/Caches/pypoetry/virtualenvs/diary-workout-tracker-backend-ZDA_NhFM-py3.11/lib/python3.11/site-packages/rest_framework/views.py", line 469, in handle_exception
    self.raise_uncaught_exception(exc)
  File "/Users/holo/Library/Caches/pypoetry/virtualenvs/diary-workout-tracker-backend-ZDA_NhFM-py3.11/lib/python3.11/site-packages/rest_framework/views.py", line 480, in raise_uncaught_exception
    raise exc
  File "/Users/holo/Library/Caches/pypoetry/virtualenvs/diary-workout-tracker-backend-ZDA_NhFM-py3.11/lib/python3.11/site-packages/rest_framework/views.py", line 506, in dispatch
    response = handler(request, *args, **kwargs)
               ^^^^^^^^^^^^^^^^^^^^^^^^^^^^^^^^^
  File "/Users/holo/Library/Caches/pypoetry/virtualenvs/diary-workout-tracker-backend-ZDA_NhFM-py3.11/lib/python3.11/site-packages/drf_spectacular/drainage.py", line 207, in wrapped_method
    return method(self, request, *args, **kwargs)
           ^^^^^^^^^^^^^^^^^^^^^^^^^^^^^^^^^^^^^^
  File "/Users/holo/Library/Caches/pypoetry/virtualenvs/diary-workout-tracker-backend-ZDA_NhFM-py3.11/lib/python3.11/site-packages/rest_framework/generics.py", line 242, in post
    return self.create(request, *args, **kwargs)
           ^^^^^^^^^^^^^^^^^^^^^^^^^^^^^^^^^^^^^
  File "/Users/holo/Dev/diary-workout-tracker-backend/backend/api/v1/views.py", line 206, in create
    updater.update_achievements()
  File "/Users/holo/Dev/diary-workout-tracker-backend/backend/utils/achievements.py", line 129, in update_achievements
    self._check_for_new_backend_achievements()
  File "/Users/holo/Dev/diary-workout-tracker-backend/backend/utils/achievements.py", line 155, in _check_for_new_backend_achievements
    if validator is not None and validator(user=self._user, history=self._history):
                                 ^^^^^^^^^^^^^^^^^^^^^^^^^^^^^^^^^^^^^^^^^^^^^^^^^
  File "/Users/holo/Dev/diary-workout-tracker-backend/backend/utils/achievements.py", line 14, in tourist
    if history.day_number == 1:
       ^^^^^^^^^^^^^^^^^^
AttributeError: 'History' object has no attribute 'day_number'
[django.request 2024-04-03 19:37:51 log.py: 241 - log_response()] Internal Server Error: /api/v1/history/
Traceback (most recent call last):
  File "/Users/holo/Library/Caches/pypoetry/virtualenvs/diary-workout-tracker-backend-ZDA_NhFM-py3.11/lib/python3.11/site-packages/django/core/handlers/exception.py", line 55, in inner
    response = get_response(request)
               ^^^^^^^^^^^^^^^^^^^^^
  File "/Users/holo/Library/Caches/pypoetry/virtualenvs/diary-workout-tracker-backend-ZDA_NhFM-py3.11/lib/python3.11/site-packages/django/core/handlers/base.py", line 197, in _get_response
    response = wrapped_callback(request, *callback_args, **callback_kwargs)
               ^^^^^^^^^^^^^^^^^^^^^^^^^^^^^^^^^^^^^^^^^^^^^^^^^^^^^^^^^^^^
  File "/Users/holo/Library/Caches/pypoetry/virtualenvs/diary-workout-tracker-backend-ZDA_NhFM-py3.11/lib/python3.11/site-packages/django/views/decorators/csrf.py", line 65, in _view_wrapper
    return view_func(request, *args, **kwargs)
           ^^^^^^^^^^^^^^^^^^^^^^^^^^^^^^^^^^^
  File "/Users/holo/Library/Caches/pypoetry/virtualenvs/diary-workout-tracker-backend-ZDA_NhFM-py3.11/lib/python3.11/site-packages/django/views/generic/base.py", line 104, in view
    return self.dispatch(request, *args, **kwargs)
           ^^^^^^^^^^^^^^^^^^^^^^^^^^^^^^^^^^^^^^^
  File "/Users/holo/Library/Caches/pypoetry/virtualenvs/diary-workout-tracker-backend-ZDA_NhFM-py3.11/lib/python3.11/site-packages/rest_framework/views.py", line 509, in dispatch
    response = self.handle_exception(exc)
               ^^^^^^^^^^^^^^^^^^^^^^^^^^
  File "/Users/holo/Library/Caches/pypoetry/virtualenvs/diary-workout-tracker-backend-ZDA_NhFM-py3.11/lib/python3.11/site-packages/rest_framework/views.py", line 469, in handle_exception
    self.raise_uncaught_exception(exc)
  File "/Users/holo/Library/Caches/pypoetry/virtualenvs/diary-workout-tracker-backend-ZDA_NhFM-py3.11/lib/python3.11/site-packages/rest_framework/views.py", line 480, in raise_uncaught_exception
    raise exc
  File "/Users/holo/Library/Caches/pypoetry/virtualenvs/diary-workout-tracker-backend-ZDA_NhFM-py3.11/lib/python3.11/site-packages/rest_framework/views.py", line 506, in dispatch
    response = handler(request, *args, **kwargs)
               ^^^^^^^^^^^^^^^^^^^^^^^^^^^^^^^^^
  File "/Users/holo/Library/Caches/pypoetry/virtualenvs/diary-workout-tracker-backend-ZDA_NhFM-py3.11/lib/python3.11/site-packages/drf_spectacular/drainage.py", line 207, in wrapped_method
    return method(self, request, *args, **kwargs)
           ^^^^^^^^^^^^^^^^^^^^^^^^^^^^^^^^^^^^^^
  File "/Users/holo/Library/Caches/pypoetry/virtualenvs/diary-workout-tracker-backend-ZDA_NhFM-py3.11/lib/python3.11/site-packages/rest_framework/generics.py", line 242, in post
    return self.create(request, *args, **kwargs)
           ^^^^^^^^^^^^^^^^^^^^^^^^^^^^^^^^^^^^^
  File "/Users/holo/Dev/diary-workout-tracker-backend/backend/api/v1/views.py", line 206, in create
    updater.update_achievements()
  File "/Users/holo/Dev/diary-workout-tracker-backend/backend/utils/achievements.py", line 129, in update_achievements
    self._check_for_new_backend_achievements()
  File "/Users/holo/Dev/diary-workout-tracker-backend/backend/utils/achievements.py", line 155, in _check_for_new_backend_achievements
    if validator is not None and validator(user=self._user, history=self._history):
                                 ^^^^^^^^^^^^^^^^^^^^^^^^^^^^^^^^^^^^^^^^^^^^^^^^^
  File "/Users/holo/Dev/diary-workout-tracker-backend/backend/utils/achievements.py", line 14, in tourist
    if history.day_number == 1:
       ^^^^^^^^^^^^^^^^^^
AttributeError: 'History' object has no attribute 'day_number'
[django.request 2024-04-03 19:37:51 log.py: 241 - log_response()] Not Found: /api/v1/resend_code/
[django.request 2024-04-03 19:37:51 log.py: 241 - log_response()] Too Many Requests: /api/v1/resend_code/
[django.request 2024-04-03 19:37:51 log.py: 241 - log_response()] Too Many Requests: /api/v1/resend_code/
[django.request 2024-04-03 19:37:51 log.py: 241 - log_response()] Too Many Requests: /api/v1/resend_code/
[django.request 2024-04-03 19:37:51 log.py: 241 - log_response()] Too Many Requests: /api/v1/resend_code/
[django.request 2024-04-03 19:37:51 log.py: 241 - log_response()] Bad Request: /api/v1/token/refresh/
[django.request 2024-04-03 19:37:51 log.py: 241 - log_response()] Bad Request: /api/v1/user/
[django.request 2024-04-03 19:37:51 log.py: 241 - log_response()] Bad Request: /api/v1/user/
[django.request 2024-04-03 19:37:51 log.py: 241 - log_response()] Bad Request: /api/v1/user/
[django.request 2024-04-03 19:37:51 log.py: 241 - log_response()] Bad Request: /api/v1/user/
[django.request 2024-04-03 19:37:51 log.py: 241 - log_response()] Bad Request: /api/v1/user/
[django.request 2024-04-03 19:37:52 log.py: 241 - log_response()] Bad Request: /api/v1/user/
[django.request 2024-04-03 19:37:52 log.py: 241 - log_response()] Unauthorized: /api/v1/me/
[django.request 2024-04-03 19:37:52 log.py: 241 - log_response()] Bad Request: /api/v1/user/
[django.request 2024-04-03 19:38:07 log.py: 241 - log_response()] Not Found: /api/v1/resend_code/
[django.request 2024-04-03 19:38:07 log.py: 241 - log_response()] Too Many Requests: /api/v1/resend_code/
[django.request 2024-04-03 19:38:07 log.py: 241 - log_response()] Too Many Requests: /api/v1/resend_code/
[django.request 2024-04-03 19:38:07 log.py: 241 - log_response()] Too Many Requests: /api/v1/resend_code/
[django.request 2024-04-03 19:38:07 log.py: 241 - log_response()] Too Many Requests: /api/v1/resend_code/
[django.request 2024-04-03 19:38:07 log.py: 241 - log_response()] Bad Request: /api/v1/token/refresh/
[django.request 2024-04-03 19:38:07 log.py: 241 - log_response()] Bad Request: /api/v1/user/
[django.request 2024-04-03 19:38:07 log.py: 241 - log_response()] Bad Request: /api/v1/user/
[django.request 2024-04-03 19:38:07 log.py: 241 - log_response()] Bad Request: /api/v1/user/
[django.request 2024-04-03 19:38:07 log.py: 241 - log_response()] Bad Request: /api/v1/user/
[django.request 2024-04-03 19:38:07 log.py: 241 - log_response()] Bad Request: /api/v1/user/
[django.request 2024-04-03 19:38:07 log.py: 241 - log_response()] Bad Request: /api/v1/user/
[django.request 2024-04-03 19:38:08 log.py: 241 - log_response()] Unauthorized: /api/v1/me/
[django.request 2024-04-03 19:38:08 log.py: 241 - log_response()] Bad Request: /api/v1/user/
[django.request 2024-04-03 19:46:57 log.py: 241 - log_response()] Not Found: /api/v1/resend_code/
[django.request 2024-04-03 19:46:57 log.py: 241 - log_response()] Too Many Requests: /api/v1/resend_code/
[django.request 2024-04-03 19:46:57 log.py: 241 - log_response()] Too Many Requests: /api/v1/resend_code/
[django.request 2024-04-03 19:46:57 log.py: 241 - log_response()] Too Many Requests: /api/v1/resend_code/
[django.request 2024-04-03 19:46:57 log.py: 241 - log_response()] Too Many Requests: /api/v1/resend_code/
[django.request 2024-04-03 19:46:57 log.py: 241 - log_response()] Bad Request: /api/v1/token/refresh/
[django.request 2024-04-03 19:46:57 log.py: 241 - log_response()] Bad Request: /api/v1/user/
[django.request 2024-04-03 19:46:57 log.py: 241 - log_response()] Bad Request: /api/v1/user/
[django.request 2024-04-03 19:46:57 log.py: 241 - log_response()] Bad Request: /api/v1/user/
[django.request 2024-04-03 19:46:57 log.py: 241 - log_response()] Bad Request: /api/v1/user/
[django.request 2024-04-03 19:46:57 log.py: 241 - log_response()] Bad Request: /api/v1/user/
[django.request 2024-04-03 19:46:57 log.py: 241 - log_response()] Bad Request: /api/v1/user/
[django.request 2024-04-03 19:46:57 log.py: 241 - log_response()] Unauthorized: /api/v1/me/
[django.request 2024-04-03 19:46:57 log.py: 241 - log_response()] Bad Request: /api/v1/user/
[django.request 2024-04-03 19:47:35 log.py: 241 - log_response()] Not Found: /api/v1/resend_code/
[django.request 2024-04-03 19:47:35 log.py: 241 - log_response()] Too Many Requests: /api/v1/resend_code/
[django.request 2024-04-03 19:47:35 log.py: 241 - log_response()] Too Many Requests: /api/v1/resend_code/
[django.request 2024-04-03 19:47:35 log.py: 241 - log_response()] Too Many Requests: /api/v1/resend_code/
[django.request 2024-04-03 19:47:35 log.py: 241 - log_response()] Too Many Requests: /api/v1/resend_code/
[django.request 2024-04-03 19:47:35 log.py: 241 - log_response()] Bad Request: /api/v1/token/refresh/
[django.request 2024-04-03 19:47:35 log.py: 241 - log_response()] Bad Request: /api/v1/user/
[django.request 2024-04-03 19:47:35 log.py: 241 - log_response()] Bad Request: /api/v1/user/
[django.request 2024-04-03 19:47:35 log.py: 241 - log_response()] Bad Request: /api/v1/user/
[django.request 2024-04-03 19:47:35 log.py: 241 - log_response()] Bad Request: /api/v1/user/
[django.request 2024-04-03 19:47:35 log.py: 241 - log_response()] Bad Request: /api/v1/user/
[django.request 2024-04-03 19:47:35 log.py: 241 - log_response()] Bad Request: /api/v1/user/
[django.request 2024-04-03 19:47:36 log.py: 241 - log_response()] Unauthorized: /api/v1/me/
[django.request 2024-04-03 19:47:36 log.py: 241 - log_response()] Bad Request: /api/v1/user/
